[2024-10-06T20:23:14.475+0000] {taskinstance.py:1159} INFO - Dependencies all met for dep_context=non-requeueable deps ti=<TaskInstance: flight_data_pipeline.upload_to_db scheduled__2024-10-05T00:00:00+00:00 [queued]>
[2024-10-06T20:23:14.485+0000] {taskinstance.py:1159} INFO - Dependencies all met for dep_context=requeueable deps ti=<TaskInstance: flight_data_pipeline.upload_to_db scheduled__2024-10-05T00:00:00+00:00 [queued]>
[2024-10-06T20:23:14.486+0000] {taskinstance.py:1361} INFO - Starting attempt 8 of 8
[2024-10-06T20:23:14.504+0000] {taskinstance.py:1382} INFO - Executing <Task(PythonOperator): upload_to_db> on 2024-10-05 00:00:00+00:00
[2024-10-06T20:23:14.511+0000] {standard_task_runner.py:57} INFO - Started process 71 to run task
[2024-10-06T20:23:14.517+0000] {standard_task_runner.py:84} INFO - Running: ['***', 'tasks', 'run', 'flight_data_pipeline', 'upload_to_db', 'scheduled__2024-10-05T00:00:00+00:00', '--job-id', '117', '--raw', '--subdir', 'DAGS_FOLDER/flights_dag.py', '--cfg-path', '/tmp/tmpylpawqy3']
[2024-10-06T20:23:14.521+0000] {standard_task_runner.py:85} INFO - Job 117: Subtask upload_to_db
[2024-10-06T20:23:14.543+0000] {logging_mixin.py:154} WARNING - /home/***/.local/lib/python3.8/site-packages/***/settings.py:195 DeprecationWarning: The sql_alchemy_conn option in [core] has been moved to the sql_alchemy_conn option in [database] - the old setting has been used, but please update your config.
[2024-10-06T20:23:14.593+0000] {task_command.py:416} INFO - Running <TaskInstance: flight_data_pipeline.upload_to_db scheduled__2024-10-05T00:00:00+00:00 [running]> on host 57ee5b1092ba
[2024-10-06T20:23:14.740+0000] {taskinstance.py:1662} INFO - Exporting env vars: AIRFLOW_CTX_DAG_OWNER='***' AIRFLOW_CTX_DAG_ID='flight_data_pipeline' AIRFLOW_CTX_TASK_ID='upload_to_db' AIRFLOW_CTX_EXECUTION_DATE='2024-10-05T00:00:00+00:00' AIRFLOW_CTX_TRY_NUMBER='8' AIRFLOW_CTX_DAG_RUN_ID='scheduled__2024-10-05T00:00:00+00:00'
[2024-10-06T20:23:14.898+0000] {taskinstance.py:1937} ERROR - Task failed with exception
Traceback (most recent call last):
  File "/home/airflow/.local/lib/python3.8/site-packages/airflow/operators/python.py", line 192, in execute
    return_value = self.execute_callable()
  File "/home/airflow/.local/lib/python3.8/site-packages/airflow/operators/python.py", line 209, in execute_callable
    return self.python_callable(*self.op_args, **self.op_kwargs)
  File "/opt/airflow/dags/flights_dag.py", line 75, in upload_to_db
    cursor.execute(
psycopg2.errors.UniqueViolation: duplicate key value violates unique constraint "testdata_pkey"
DETAIL:  Key (flight_date, flight_number)=(2024-10-07, 975) already exists.

[2024-10-06T20:23:14.911+0000] {taskinstance.py:1400} INFO - Marking task as FAILED. dag_id=flight_data_pipeline, task_id=upload_to_db, execution_date=20241005T000000, start_date=20241006T202314, end_date=20241006T202314
[2024-10-06T20:23:14.926+0000] {standard_task_runner.py:104} ERROR - Failed to execute job 117 for task upload_to_db (duplicate key value violates unique constraint "testdata_pkey"
DETAIL:  Key (flight_date, flight_number)=(2024-10-07, 975) already exists.
; 71)
[2024-10-06T20:23:14.955+0000] {local_task_job_runner.py:228} INFO - Task exited with return code 1
[2024-10-06T20:23:14.977+0000] {taskinstance.py:2778} INFO - 0 downstream tasks scheduled from follow-on schedule check
